<?xml version="1.0" ?>

<robot name="universal_robot_gripper">
  <!--################################################
  ########              arm                    #######
  ####################################################-->

  <link name="base_link">
    <visual>
      <geometry>
        <mesh filename="../meshes/ur5/visual/base.obj"/>
      </geometry>
      <material name="LightGrey">
        <color rgba="0.7 0.7 0.7 1.0"/>
      </material>
    </visual>
    <collision>
      <geometry>
        <mesh filename="../meshes/ur5/collision/base.stl"/>
      </geometry>
    </collision>
    <inertial>
      <mass value="4.0"/>
      <origin rpy="0 0 0" xyz="0.0 0.0 0.0"/>
      <inertia ixx="0.00443333156" ixy="0.0" ixz="0.0" iyy="0.00443333156" iyz="0.0" izz="0.0072"/>
    </inertial>
  </link>

  <joint name="shoulder_pan_joint" type="revolute">
    <parent link="base_link"/>
    <child link="shoulder_link"/>
    <origin rpy="0.0 0.0 0.0" xyz="0.0 0.0 0.089159"/>
    <axis xyz="0 0 1"/>
    <limit effort="150.0" lower="-6.28318530718" upper="6.28318530718" velocity="3.15"/>
    <dynamics damping="0.0" friction="0.0"/>
  </joint>


  <link name="shoulder_link">
    <visual>
      <geometry>
        <mesh filename="../meshes/ur5/visual/shoulder.obj"/>
      </geometry>
      <material name="LightGrey">
        <color rgba="0.7 0.7 0.7 1.0"/>
      </material>
    </visual>
    <collision>
      <geometry>
        <mesh filename="../meshes/ur5/collision/shoulder.stl"/>
      </geometry>
    </collision>
    <inertial>
      <mass value="3.7"/>
      <origin rpy="0 0 0" xyz="0.0 0.0 0.0"/>
      <inertia ixx="0.010267495893" ixy="0.0" ixz="0.0" iyy="0.010267495893" iyz="0.0" izz="0.00666"/>
    </inertial>
  </link>
  <joint name="shoulder_lift_joint" type="revolute">
    <parent link="shoulder_link"/>
    <child link="upper_arm_link"/>
    <origin rpy="0.0 1.57079632679 0.0" xyz="0.0 0.13585 0.0"/>
    <axis xyz="0 1 0"/>
    <limit effort="150.0" lower="-6.28318530718" upper="6.28318530718" velocity="3.15"/>
    <dynamics damping="0.0" friction="0.0"/>
  </joint>
  <link name="upper_arm_link">
    <visual>
      <geometry>
        <mesh filename="../meshes/ur5/visual/upperarm.obj"/>
      </geometry>
      <material name="LightGrey">
        <color rgba="0.7 0.7 0.7 1.0"/>
      </material>
    </visual>
    <collision>
      <geometry>
        <mesh filename="../meshes/ur5/collision/upperarm.stl"/>
      </geometry>
    </collision>
    <inertial>
      <mass value="8.393"/>
      <origin rpy="0 0 0" xyz="0.0 0.0 0.28"/>
      <inertia ixx="0.22689067591" ixy="0.0" ixz="0.0" iyy="0.22689067591" iyz="0.0" izz="0.0151074"/>
    </inertial>
  </link>
  <joint name="elbow_joint" type="revolute">
    <parent link="upper_arm_link"/>
    <child link="forearm_link"/>
    <origin rpy="0.0 0.0 0.0" xyz="0.0 -0.1197 0.425"/>
    <axis xyz="0 1 0"/>
    <limit effort="150.0" lower="-3.14159265359" upper="3.14159265359" velocity="3.15"/>
    <dynamics damping="0.0" friction="0.0"/>
  </joint>
  <link name="forearm_link">
    <visual>
      <geometry>
        <mesh filename="../meshes/ur5/visual/forearm.obj"/>
      </geometry>
      <material name="LightGrey">
        <color rgba="0.7 0.7 0.7 1.0"/>
      </material>
    </visual>
    <collision>
      <geometry>
        <mesh filename="../meshes/ur5/collision/forearm.stl"/>
      </geometry>
    </collision>
    <inertial>
      <mass value="2.275"/>
      <origin rpy="0 0 0" xyz="0.0 0.0 0.25"/>
      <inertia ixx="0.049443313556" ixy="0.0" ixz="0.0" iyy="0.049443313556" iyz="0.0" izz="0.004095"/>
    </inertial>
  </link>
  <joint name="wrist_1_joint" type="revolute">
    <parent link="forearm_link"/>
    <child link="wrist_1_link"/>
    <origin rpy="0.0 1.57079632679 0.0" xyz="0.0 0.0 0.39225"/>
    <axis xyz="0 1 0"/>
    <limit effort="28.0" lower="-6.28318530718" upper="6.28318530718" velocity="3.2"/>
    <dynamics damping="0.0" friction="0.0"/>
  </joint>
  <link name="wrist_1_link">
    <visual>
      <geometry>
        <mesh filename="../meshes/ur5/visual/wrist1.obj"/>
      </geometry>
      <material name="LightGrey">
        <color rgba="0.7 0.7 0.7 1.0"/>
      </material>
    </visual>
    <collision>
      <geometry>
        <mesh filename="../meshes/ur5/collision/wrist1.stl"/>
      </geometry>
    </collision>
    <inertial>
      <mass value="1.219"/>
      <origin rpy="0 0 0" xyz="0.0 0.0 0.0"/>
      <inertia ixx="0.111172755531" ixy="0.0" ixz="0.0" iyy="0.111172755531" iyz="0.0" izz="0.21942"/>
    </inertial>
  </link>
  <joint name="wrist_2_joint" type="revolute">
    <parent link="wrist_1_link"/>
    <child link="wrist_2_link"/>
    <origin rpy="0.0 0.0 0.0" xyz="0.0 0.093 0.0"/>
    <axis xyz="0 0 1"/>
    <limit effort="28.0" lower="-6.28318530718" upper="6.28318530718" velocity="3.2"/>
    <dynamics damping="0.0" friction="0.0"/>
  </joint>
  <link name="wrist_2_link">
    <visual>
      <geometry>
        <mesh filename="../meshes/ur5/visual/wrist2.obj"/>
      </geometry>
      <material name="LightGrey">
        <color rgba="0.7 0.7 0.7 1.0"/>
      </material>
    </visual>
    <collision>
      <geometry>
        <mesh filename="../meshes/ur5/collision/wrist2.stl"/>
      </geometry>
    </collision>
    <inertial>
      <mass value="1.219"/>
      <origin rpy="0 0 0" xyz="0.0 0.0 0.0"/>
      <inertia ixx="0.111172755531" ixy="0.0" ixz="0.0" iyy="0.111172755531" iyz="0.0" izz="0.21942"/>
    </inertial>
  </link>
  <joint name="wrist_3_joint" type="revolute">
    <parent link="wrist_2_link"/>
    <child link="wrist_3_link"/>
    <origin rpy="0.0 0.0 0.0" xyz="0.0 0.0 0.09465"/>
    <axis xyz="0 1 0"/>
    <limit effort="28.0" lower="-6.28318530718" upper="6.28318530718" velocity="3.2"/>
    <dynamics damping="0.0" friction="0.0"/>
  </joint>
  <link name="wrist_3_link">
    <visual>
      <geometry>
        <mesh filename="../meshes/ur5/visual/wrist3.obj"/>
      </geometry>
      <material name="LightGrey">
        <color rgba="0.7 0.7 0.7 1.0"/>
      </material>
    </visual>
    <collision>
      <geometry>
        <mesh filename="../meshes/ur5/collision/wrist3.stl"/>
      </geometry>
    </collision>
    <inertial>
      <mass value="0.1879"/>
      <origin rpy="0 0 0" xyz="0.0 0.0 0.0"/>
      <inertia ixx="0.0171364731454" ixy="0.0" ixz="0.0" iyy="0.0171364731454" iyz="0.0" izz="0.033822"/>
    </inertial>
  </link>


  <!-- <joint name="ee_fixed_joint" type="fixed">
    <parent link="wrist_3_link"/>
    <child link="ee_link"/>
    <origin rpy="0.0 0.0 1.57079632679" xyz="0.0 0.0823 0.0"/>
  </joint>

  <link name="ee_link">
    <visual>
      <geometry>
        <box size="0.05 0.05 0.05"/>
      </geometry>
      <material name="YELLOW">
        <color rgba="0.9 0.9 0.1 1.0"/>
      </material>
      <origin rpy="0 0 0" xyz="0.03 0 0"/>
    </visual>
    <collision>
      <geometry>
        <box size="0.05 0.05 0.05"/>
      </geometry>
      <origin rpy="0 0 0" xyz="-0.01 0 0"/>
    </collision>
    <inertial>
      <mass value="0.2"/>
      <origin rpy="0 0 0" xyz="0.0 0.0 0.0"/>
      <inertia ixx="0.000083" ixy="0.0" ixz="0.0" iyy="0.000083" iyz="0.0" izz="0.000083"/>
    </inertial>
  </link> -->

  <!--################################################
  ########              gripper                  #####
  ####################################################-->

  <!-- base -->
  <link name="simple_gripper_base">
    <!-- inertial>
        <mass value="0.1"/>
        <origin xyz="0 0 0.055"  />
        <cylinder_inertia radius="0.06" length="0.11" mass="0.1"/>
      </inertial -->
    <visual>
      <geometry>
        <mesh filename="../meshes/c85/visual/base.dae" scale="0.001 0.001 0.001"/>
      </geometry>
    </visual>
    <collision>
      <origin rpy="0 0 0" xyz="0 0 0.015"/>
      <geometry>
        <cylinder length="0.045" radius="0.04"/>
      </geometry>
    </collision>
    <collision>
      <origin rpy="0 0 0" xyz="0 0 0.06"/>
      <geometry>
        <box size="0.03 0.04 0.06"/>
      </geometry>
    </collision>
  </link>
  
  <!-- right finger -->
  <joint name="simple_gripper_right_driver_joint" type="revolute">
    <origin rpy="0 0 0" xyz="0 0.0306011 0.054904"/>
    <parent link="simple_gripper_base"/>
    <child link="simple_gripper_right_driver"/>
    <axis xyz="1 0 0"/>
    <limit effort="176" lower="0.0" upper="0.7155848444444445" velocity="1.919861777777778"/>
  </joint>
  <link name="simple_gripper_right_driver">
    <!-- inertial>
        <mass value="0.1"/>
        <origin xyz="0 0 0.055"  />
        <cylinder_inertia radius="0.06" length="0.11" mass="0.1"/>
      </inertial -->
    <visual>
      <geometry>
        <mesh filename="../meshes/c85/visual/driver.dae" scale="0.001 0.001 0.001"/>
      </geometry>
    </visual>
    <collision>
      <origin rpy="-0.1 0 0" xyz="0 0.02 0"/>
      <geometry>
        <box size="0.04 0.04 0.02"/>
      </geometry>
    </collision>
  </link>
  <joint name="simple_gripper_right_coupler_joint" type="fixed">
    <origin rpy="0 0 0" xyz="0 0.0315 -0.0041"/>
    <parent link="simple_gripper_right_driver"/>
    <child link="simple_gripper_right_coupler"/>
  </joint>
  <link name="simple_gripper_right_coupler">
    <!-- inertial>
        <mass value="0.1"/>
        <origin xyz="0 0 0.055"  />
        <cylinder_inertia radius="0.06" length="0.11" mass="0.1"/>
      </inertial -->
    <visual>
      <geometry>
        <mesh filename="../meshes/c85/visual/coupler.dae" scale="0.001 0.001 0.001"/>
      </geometry>
    </visual>
    <collision>
      <origin rpy="-1.7 0 0" xyz="0 0.0 0.025"/>
      <geometry>
        <box size="0.04 0.065 0.02"/>
      </geometry>
    </collision>
  </link>
  <joint name="simple_gripper_right_follower_joint" type="revolute">
    <origin rpy="0 0 0" xyz="0 0.0061 0.0471"/>
    <parent link="simple_gripper_right_coupler"/>
    <child link="simple_gripper_right_follower"/>
    <axis xyz="1 0 0"/>
    <limit effort="176" lower="-2.9670591111111113" upper="2.9670591111111113" velocity="1.919861777777778"/>
    <mimic joint="simple_gripper_right_driver_joint" multiplier="-1"/>
  </joint>
  <link name="simple_gripper_right_follower">
    <!-- inertial>
        <mass value="0.1"/>
        <origin xyz="0 0 0.055"  />
        <cylinder_inertia radius="0.06" length="0.11" mass="0.1"/>
      </inertial -->
    <visual>
      <geometry>
        <mesh filename="../meshes/c85/visual/follower.dae" scale="0.001 0.001 0.001"/>
      </geometry>
    </visual>
    <collision>
      <origin rpy="0 0 0" xyz="0 -0.02 0.03"/>
      <geometry>
        <box size="0.04 0.02 0.06"/>
      </geometry>
    </collision>
  </link>
  <joint name="simple_gripper_right_pad_joint" type="fixed">
    <parent link="simple_gripper_right_follower"/>
    <child link="simple_gripper_right_pad"/>
  </joint>
  <link name="simple_gripper_right_pad">
    <!-- inertial>
        <mass value="0.1"/>
        <origin xyz="0 0 0.055"  />
        <cylinder_inertia radius="0.06" length="0.11" mass="0.1"/>
      </inertial -->
    <visual>
      <geometry>
        <mesh filename="../meshes/c85/visual/pad.dae" scale="0.001 0.001 0.001"/>
      </geometry>
    </visual>
    <collision>
      <origin rpy="0 0 0" xyz="0 -0.02 0.03"/>
      <geometry>
        <box size="0.04 0.02 0.06"/>
      </geometry>
    </collision>
  </link>
  <joint name="simple_gripper_right_spring_link_joint" type="revolute">
    <origin rpy="0 0 0" xyz="0 0.012 0.0614"/>
    <parent link="simple_gripper_base"/>
    <child link="simple_gripper_right_spring_link"/>
    <axis xyz="1 0 0"/>
    <limit effort="176" lower="-2.9670591111111113" upper="2.9670591111111113" velocity="1.919861777777778"/>
    <mimic joint="simple_gripper_right_driver_joint" multiplier="1"/>
  </joint>
  <link name="simple_gripper_right_spring_link">
    <!-- inertial>
        <mass value="0.1"/>
        <origin xyz="0 0 0.055"  />
        <cylinder_inertia radius="0.06" length="0.11" mass="0.1"/>
      </inertial -->
    <visual>
      <geometry>
        <mesh filename="../meshes/c85/visual/spring_link.dae" scale="0.001 0.001 0.001"/>
      </geometry>
    </visual>
    <collision>
      <origin rpy="-0.7068 0 0" xyz="0 0.018 0.018"/>
      <geometry>
        <box size="0.04 0.02 0.065"/>
      </geometry>
    </collision>
  </link>
  <!-- left finger -->
  <joint name="simple_gripper_left_driver_joint" type="revolute">
    <origin rpy="0 0 3.141592653589793" xyz="0 -0.0306011 0.054904"/>
    <parent link="simple_gripper_base"/>
    <child link="simple_gripper_left_driver"/>
    <axis xyz="1 0 0"/>
    <limit effort="176" lower="0.0" upper="0.7155848444444445" velocity="1.919861777777778"/>
    <mimic joint="simple_gripper_right_driver_joint" multiplier="1"/>
  </joint>
  <link name="simple_gripper_left_driver">
    <!-- inertial>
        <mass value="0.1"/>
        <origin xyz="0 0 0.055"  />
        <cylinder_inertia radius="0.06" length="0.11" mass="0.1"/>
      </inertial -->
    <visual>
      <geometry>
        <mesh filename="../meshes/c85/visual/driver.dae" scale="0.001 0.001 0.001"/>
      </geometry>
    </visual>
    <collision>
      <origin rpy="-0.1 0 0" xyz="0 0.02 0"/>
      <geometry>
        <box size="0.04 0.04 0.02"/>
      </geometry>
    </collision>
  </link>
  <joint name="simple_gripper_left_coupler_joint" type="fixed">
    <origin rpy="0 0 0" xyz="0 0.0315 -0.0041"/>
    <parent link="simple_gripper_left_driver"/>
    <child link="simple_gripper_left_coupler"/>
  </joint>
  <link name="simple_gripper_left_coupler">
    <!-- inertial>
        <mass value="0.1"/>
        <origin xyz="0 0 0.055"  />
        <cylinder_inertia radius="0.06" length="0.11" mass="0.1"/>
      </inertial -->
    <visual>
      <geometry>
        <mesh filename="../meshes/c85/visual/coupler.dae" scale="0.001 0.001 0.001"/>
      </geometry>
    </visual>
    <collision>
      <origin rpy="-1.7 0 0" xyz="0 0.0 0.025"/>
      <geometry>
        <box size="0.04 0.065 0.02"/>
      </geometry>
    </collision>
  </link>
  <joint name="simple_gripper_left_follower_joint" type="revolute">
    <origin rpy="0 0 0" xyz="0 0.0061 0.0471"/>
    <parent link="simple_gripper_left_coupler"/>
    <child link="simple_gripper_left_follower"/>
    <axis xyz="1 0 0"/>
    <limit effort="176" lower="-2.9670591111111113" upper="2.9670591111111113" velocity="1.919861777777778"/>
    <mimic joint="simple_gripper_right_driver_joint" multiplier="-1"/>
  </joint>
  <link name="simple_gripper_left_follower">
    <!-- inertial>
        <mass value="0.1"/>
        <origin xyz="0 0 0.055"  />
        <cylinder_inertia radius="0.06" length="0.11" mass="0.1"/>
      </inertial -->
    <visual>
      <geometry>
        <mesh filename="../meshes/c85/visual/follower.dae" scale="0.001 0.001 0.001"/>
      </geometry>
    </visual>
    <collision>
      <origin rpy="0 0 0" xyz="0 -0.02 0.03"/>
      <geometry>
        <box size="0.04 0.02 0.06"/>
      </geometry>
    </collision>
  </link>
  <joint name="simple_gripper_left_pad_joint" type="fixed">
    <parent link="simple_gripper_left_follower"/>
    <child link="simple_gripper_left_pad"/>
  </joint>
  <link name="simple_gripper_left_pad">
    <!-- inertial>
        <mass value="0.1"/>
        <origin xyz="0 0 0.055"  />
        <cylinder_inertia radius="0.06" length="0.11" mass="0.1"/>
      </inertial -->
    <visual>
      <geometry>
        <mesh filename="../meshes/c85/visual/pad.dae" scale="0.001 0.001 0.001"/>
      </geometry>
    </visual>
    <collision>
      <origin rpy="0 0 0" xyz="0 -0.02 0.03"/>
      <geometry>
        <box size="0.04 0.02 0.06"/>
      </geometry>
    </collision>
  </link>
  <joint name="simple_gripper_left_spring_link_joint" type="revolute">
    <origin rpy="0 0 3.141592653589793" xyz="0 -0.012 0.0614"/>
    <parent link="simple_gripper_base"/>
    <child link="simple_gripper_left_spring_link"/>
    <axis xyz="1 0 0"/>
    <limit effort="176" lower="-2.9670591111111113" upper="2.9670591111111113" velocity="1.919861777777778"/>
    <mimic joint="simple_gripper_right_driver_joint" multiplier="1"/>
  </joint>
  <link name="simple_gripper_left_spring_link">
    <!-- inertial>
        <mass value="0.1"/>
        <origin xyz="0 0 0.055"  />
        <cylinder_inertia radius="0.06" length="0.11" mass="0.1"/>
      </inertial -->
    <visual>
      <geometry>
        <mesh filename="../meshes/c85/visual/spring_link.dae" scale="0.001 0.001 0.001"/>
      </geometry>
    </visual>
    <collision>
      <origin rpy="-0.7068 0 0" xyz="0 0.018 0.018"/>
      <geometry>
        <box size="0.04 0.02 0.065"/>
      </geometry>
    </collision>
  </link>


  

  <!--################################################
  ########          connect model                #####
  ####################################################-->

  <!-- connect arm to world -->
  <link name="world"/>
  <joint name="world_joint" type="fixed">
    <parent link="world"/>
    <child link="base_link"/>
    <origin rpy="0.0 0.0 0.0" xyz="0.0 0.0 0.3"/>
  </joint>

  <!-- connect gripper to arm -->
  <joint name="arm_gripper_joint" type="fixed">
    <parent link="wrist_3_link"/>
    <child link="simple_gripper_base"/>
    <origin rpy="-1.57 0.0 0.0" xyz="0.0 0.085 0.0"/>
  </joint>

</robot>


